<mujoco model="g1_12dof">
  <compiler angle="radian" meshdir="meshes/"/>

  <statistic meansize="0.144785" extent="1.23314" center="0.025392 2.0634e-05 -0.245975"/>
  <default>
    <joint damping="0.001" armature="0.01" frictionloss="0.1"/>
  </default>

  <asset>
    <mesh name="pelvis" file="pelvis.STL"/>
    <mesh name="pelvis_contour_link" file="pelvis_contour_link.STL"/>
    <mesh name="left_hip_pitch_link" file="left_hip_pitch_link.STL"/>
    <mesh name="left_hip_roll_link" file="left_hip_roll_link.STL"/>
    <mesh name="left_hip_yaw_link" file="left_hip_yaw_link.STL"/>
    <mesh name="left_knee_link" file="left_knee_link.STL"/>
    <mesh name="left_ankle_pitch_link" file="left_ankle_pitch_link.STL"/>
    <mesh name="left_ankle_roll_link" file="left_ankle_roll_link.STL"/>
    <mesh name="right_hip_pitch_link" file="right_hip_pitch_link.STL"/>
    <mesh name="right_hip_roll_link" file="right_hip_roll_link.STL"/>
    <mesh name="right_hip_yaw_link" file="right_hip_yaw_link.STL"/>
    <mesh name="right_knee_link" file="right_knee_link.STL"/>
    <mesh name="right_ankle_pitch_link" file="right_ankle_pitch_link.STL"/>
    <mesh name="right_ankle_roll_link" file="right_ankle_roll_link.STL"/>
    <mesh name="torso_link_23dof_rev_1_0" file="torso_link_23dof_rev_1_0.STL"/>
    <mesh name="logo_link" file="logo_link.STL"/>
    <mesh name="head_link" file="head_link.STL"/>
    <mesh name="left_shoulder_pitch_link" file="left_shoulder_pitch_link.STL"/>
    <mesh name="left_shoulder_roll_link" file="left_shoulder_roll_link.STL"/>
    <mesh name="left_shoulder_yaw_link" file="left_shoulder_yaw_link.STL"/>
    <mesh name="left_elbow_link" file="left_elbow_link.STL"/>
    <mesh name="left_wrist_roll_rubber_hand" file="left_wrist_roll_rubber_hand.STL"/>
    <mesh name="right_shoulder_pitch_link" file="right_shoulder_pitch_link.STL"/>
    <mesh name="right_shoulder_roll_link" file="right_shoulder_roll_link.STL"/>
    <mesh name="right_shoulder_yaw_link" file="right_shoulder_yaw_link.STL"/>
    <mesh name="right_elbow_link" file="right_elbow_link.STL"/>
    <mesh name="right_wrist_roll_rubber_hand" file="right_wrist_roll_rubber_hand.STL"/>
  </asset>

  <worldbody>
    <body name="pelvis" pos="0 0 0.793">
      <inertial pos="0.0144905 0.000151462 0.144068" quat="0.999881 -0.000505543 -0.0154276 0.000328408" mass="17.7349" diaginertia="0.552723 0.454092 0.211762"/>
      <joint name="floating_base_joint" type="free" limited="false" actuatorfrclimited="false"/>
      <geom type="mesh" contype="0" conaffinity="0" group="1" density="0" rgba="0.2 0.2 0.2 1" mesh="pelvis"/>
      <geom type="mesh" contype="0" conaffinity="0" group="1" density="0" rgba="0.7 0.7 0.7 1" mesh="pelvis_contour_link"/>
      <geom type="mesh" rgba="0.7 0.7 0.7 1" mesh="pelvis_contour_link"/>
      <geom type="mesh" contype="0" conaffinity="0" group="1" density="0" rgba="0.7 0.7 0.7 1" mesh="torso_link_23dof_rev_1_0"/>
      <geom type="mesh" rgba="0.7 0.7 0.7 1" mesh="torso_link_23dof_rev_1_0"/>
      <geom type="mesh" contype="0" conaffinity="0" group="1" density="0" rgba="0.2 0.2 0.2 1" mesh="logo_link"/>
      <geom type="mesh" rgba="0.2 0.2 0.2 1" mesh="logo_link"/>
      <geom type="mesh" contype="0" conaffinity="0" group="1" density="0" rgba="0.2 0.2 0.2 1" mesh="head_link"/>
      <geom type="mesh" rgba="0.2 0.2 0.2 1" mesh="head_link"/>
      <!-- Camera in robot's head (like real G1's Intel RealSense) -->
      <!-- Tilted 15° down for better ground/obstacle visibility -->
      <camera name="head_camera" pos="0.05 0 0.35" xyaxes="0 -1 0 0.259 0 0.966" fovy="60"/>
      <!-- IMU site in pelvis -->
      <site name="imu_site" pos="0 0 0.1" size="0.01"/>

      <!-- ============================================ -->
      <!-- LiDAR sensor (36 rays, 10° apart = 360° coverage) -->
      <!-- Mounted at head height, similar to Livox MID-360 -->
      <!-- Tilted 15° downward to detect floor-level obstacles -->
      <!-- euler Y=1.8326 = 105° (90° forward + 15° down) -->
      <!-- group=4 so it's visible in viewer but hidden from robot camera -->
      <!-- ============================================ -->
      <replicate count="36" sep="-" offset="0 0 0" euler="0 0 0.1745329">
        <site name="lidar" pos="0.05 0 0.35" size="0.005" euler="0 1.8326 0" rgba="1 1 0 0.9" group="4"/>
      </replicate>
      <geom pos="-7.2e-06 0.10022 0.29178" quat="0.990264 0.139201 1.38722e-05 -9.86868e-05" type="mesh" contype="0" conaffinity="0" group="1" density="0" rgba="0.7 0.7 0.7 1" mesh="left_shoulder_pitch_link"/>
      <geom size="0.03 0.025" pos="7.72569e-07 0.141427 0.293195" quat="0.700213 0.0985001 0.700232 0.0983605" type="cylinder" rgba="0.7 0.7 0.7 1"/>
      <geom pos="3.73942e-07 0.14056 0.288961" quat="1 3.00026e-05 2.74716e-05 -9.57958e-05" type="mesh" contype="0" conaffinity="0" group="1" density="0" rgba="0.7 0.7 0.7 1" mesh="left_shoulder_roll_link"/>
      <geom size="0.03 0.015" pos="-0.00400139 0.146564 0.235962" quat="1 3.00026e-05 2.74716e-05 -9.57958e-05" type="cylinder" rgba="0.7 0.7 0.7 1"/>
      <geom pos="-4.10007e-06 0.146807 0.185762" quat="1 3.00026e-05 2.74716e-05 -9.57958e-05" type="mesh" contype="0" conaffinity="0" group="1" density="0" rgba="0.7 0.7 0.7 1" mesh="left_shoulder_yaw_link"/>
      <geom pos="-4.10007e-06 0.146807 0.185762" quat="1 3.00026e-05 2.74716e-05 -9.57958e-05" type="mesh" rgba="0.7 0.7 0.7 1" mesh="left_shoulder_yaw_link"/>
      <geom pos="0.0157745 0.146808 0.105243" quat="1 3.00026e-05 2.74716e-05 -9.57958e-05" type="mesh" contype="0" conaffinity="0" group="1" density="0" rgba="0.7 0.7 0.7 1" mesh="left_elbow_link"/>
      <geom pos="0.0157745 0.146808 0.105243" quat="1 3.00026e-05 2.74716e-05 -9.57958e-05" type="mesh" rgba="0.7 0.7 0.7 1" mesh="left_elbow_link"/>
      <geom pos="0.115774 0.148678 0.0952374" quat="1 3.00026e-05 2.74716e-05 -9.57958e-05" type="mesh" contype="0" conaffinity="0" group="1" density="0" rgba="0.7 0.7 0.7 1" mesh="left_wrist_roll_rubber_hand"/>
      <geom pos="0.115774 0.148678 0.0952374" quat="1 3.00026e-05 2.74716e-05 -9.57958e-05" type="mesh" rgba="0.7 0.7 0.7 1" mesh="left_wrist_roll_rubber_hand"/>
      <geom pos="-7.2e-06 -0.10021 0.29178" quat="0.990264 -0.139201 1.38722e-05 9.86868e-05" type="mesh" contype="0" conaffinity="0" group="1" density="0" rgba="0.7 0.7 0.7 1" mesh="right_shoulder_pitch_link"/>
      <geom size="0.03 0.025" pos="7.72569e-07 -0.141417 0.293195" quat="0.700213 -0.0985001 0.700232 -0.0983605" type="cylinder" rgba="0.7 0.7 0.7 1"/>
      <geom pos="3.73942e-07 -0.14055 0.288961" quat="1 -3.00026e-05 2.74716e-05 9.57958e-05" type="mesh" contype="0" conaffinity="0" group="1" density="0" rgba="0.7 0.7 0.7 1" mesh="right_shoulder_roll_link"/>
      <geom size="0.03 0.015" pos="-0.00400139 -0.146554 0.235962" quat="1 -3.00026e-05 2.74716e-05 9.57958e-05" type="cylinder" rgba="0.7 0.7 0.7 1"/>
      <geom pos="-4.10007e-06 -0.146797 0.185762" quat="1 -3.00026e-05 2.74716e-05 9.57958e-05" type="mesh" contype="0" conaffinity="0" group="1" density="0" rgba="0.7 0.7 0.7 1" mesh="right_shoulder_yaw_link"/>
      <geom pos="-4.10007e-06 -0.146797 0.185762" quat="1 -3.00026e-05 2.74716e-05 9.57958e-05" type="mesh" rgba="0.7 0.7 0.7 1" mesh="right_shoulder_yaw_link"/>
      <geom pos="0.0157745 -0.146798 0.105243" quat="1 -3.00026e-05 2.74716e-05 9.57958e-05" type="mesh" contype="0" conaffinity="0" group="1" density="0" rgba="0.7 0.7 0.7 1" mesh="right_elbow_link"/>
      <geom pos="0.0157745 -0.146798 0.105243" quat="1 -3.00026e-05 2.74716e-05 9.57958e-05" type="mesh" rgba="0.7 0.7 0.7 1" mesh="right_elbow_link"/>
      <geom pos="0.115774 -0.148668 0.0952374" quat="1 -3.00026e-05 2.74716e-05 9.57958e-05" type="mesh" contype="0" conaffinity="0" group="1" density="0" rgba="0.7 0.7 0.7 1" mesh="right_wrist_roll_rubber_hand"/>
      <geom pos="0.115774 -0.148668 0.0952374" quat="1 -3.00026e-05 2.74716e-05 9.57958e-05" type="mesh" rgba="0.7 0.7 0.7 1" mesh="right_wrist_roll_rubber_hand"/>
      <body name="left_hip_pitch_link" pos="0 0.064452 -0.1027">
        <inertial pos="0.002741 0.047791 -0.02606" quat="0.954862 0.293964 0.0302556 0.030122" mass="1.35" diaginertia="0.00181517 0.00153422 0.00116212"/>
        <joint name="left_hip_pitch_joint" pos="0 0 0" axis="0 1 0" range="-2.5307 2.8798" actuatorfrcrange="-88 88"/>
        <geom type="mesh" contype="0" conaffinity="0" group="1" density="0" rgba="0.2 0.2 0.2 1" mesh="left_hip_pitch_link"/>
        <geom type="mesh" rgba="0.2 0.2 0.2 1" mesh="left_hip_pitch_link"/>
        <body name="left_hip_roll_link" pos="0 0.052 -0.030465" quat="0.996179 0 -0.0873386 0">
          <inertial pos="0.029812 -0.001045 -0.087934" quat="0.977808 -1.97119e-05 0.205576 -0.0403793" mass="1.52" diaginertia="0.00254986 0.00241169 0.00148755"/>
          <joint name="left_hip_roll_joint" pos="0 0 0" axis="1 0 0" range="-0.5236 2.9671" actuatorfrcrange="-139 139"/>
          <geom type="mesh" contype="0" conaffinity="0" group="1" density="0" rgba="0.7 0.7 0.7 1" mesh="left_hip_roll_link"/>
          <geom type="mesh" rgba="0.7 0.7 0.7 1" mesh="left_hip_roll_link"/>
          <body name="left_hip_yaw_link" pos="0.025001 0 -0.12412">
            <inertial pos="-0.057709 -0.010981 -0.15078" quat="0.600598 0.15832 0.223482 0.751181" mass="1.702" diaginertia="0.00776166 0.00717575 0.00160139"/>
            <joint name="left_hip_yaw_joint" pos="0 0 0" axis="0 0 1" range="-2.7576 2.7576" actuatorfrcrange="-88 88"/>
            <geom type="mesh" contype="0" conaffinity="0" group="1" density="0" rgba="0.7 0.7 0.7 1" mesh="left_hip_yaw_link"/>
            <geom type="mesh" rgba="0.7 0.7 0.7 1" mesh="left_hip_yaw_link"/>
            <body name="left_knee_link" pos="-0.078273 0.0021489 -0.17734" quat="0.996179 0 0.0873386 0">
              <inertial pos="0.005457 0.003964 -0.12074" quat="0.923418 -0.0327699 0.0158246 0.382067" mass="1.932" diaginertia="0.0113804 0.0112778 0.00146458"/>
              <joint name="left_knee_joint" pos="0 0 0" axis="0 1 0" range="-0.087267 2.8798" actuatorfrcrange="-139 139"/>
              <geom type="mesh" contype="0" conaffinity="0" group="1" density="0" rgba="0.7 0.7 0.7 1" mesh="left_knee_link"/>
              <geom type="mesh" rgba="0.7 0.7 0.7 1" mesh="left_knee_link"/>
              <body name="left_ankle_pitch_link" pos="0 -9.4445e-05 -0.30001">
                <inertial pos="-0.007269 0 0.011137" quat="0.603053 0.369225 0.369225 0.603053" mass="0.074" diaginertia="1.89e-05 1.40805e-05 6.9195e-06"/>
                <joint name="left_ankle_pitch_joint" pos="0 0 0" axis="0 1 0" range="-0.87267 0.5236" actuatorfrcrange="-50 50"/>
                <geom type="mesh" contype="0" conaffinity="0" group="1" density="0" rgba="0.7 0.7 0.7 1" mesh="left_ankle_pitch_link"/>
                <geom type="mesh" rgba="0.7 0.7 0.7 1" mesh="left_ankle_pitch_link"/>
                <body name="left_ankle_roll_link" pos="0 0 -0.017558">
                  <inertial pos="0.026505 0 -0.016425" quat="-0.000481092 0.728482 -0.000618967 0.685065" mass="0.608" diaginertia="0.00167218 0.0016161 0.000217621"/>
                  <joint name="left_ankle_roll_joint" pos="0 0 0" axis="1 0 0" range="-0.2618 0.2618" actuatorfrcrange="-50 50"/>
                  <geom type="mesh" contype="0" conaffinity="0" group="1" density="0" rgba="0.2 0.2 0.2 1" mesh="left_ankle_roll_link"/>
                  <geom size="0.005" pos="-0.05 0.025 -0.03" rgba="0.2 0.2 0.2 1"/>
                  <geom size="0.005" pos="-0.05 -0.025 -0.03" rgba="0.2 0.2 0.2 1"/>
                  <geom size="0.005" pos="0.12 0.03 -0.03" rgba="0.2 0.2 0.2 1"/>
                  <geom size="0.005" pos="0.12 -0.03 -0.03" rgba="0.2 0.2 0.2 1"/>
                  <!-- Left foot contact site -->
                  <site name="left_foot_site" pos="0.03 0 -0.03" size="0.01"/>
                </body>
              </body>
            </body>
          </body>
        </body>
      </body>
      <body name="right_hip_pitch_link" pos="0 -0.064452 -0.1027">
        <inertial pos="0.002741 -0.047791 -0.02606" quat="0.954862 -0.293964 0.0302556 -0.030122" mass="1.35" diaginertia="0.00181517 0.00153422 0.00116212"/>
        <joint name="right_hip_pitch_joint" pos="0 0 0" axis="0 1 0" range="-2.5307 2.8798" actuatorfrcrange="-88 88"/>
        <geom type="mesh" contype="0" conaffinity="0" group="1" density="0" rgba="0.2 0.2 0.2 1" mesh="right_hip_pitch_link"/>
        <geom type="mesh" rgba="0.2 0.2 0.2 1" mesh="right_hip_pitch_link"/>
        <body name="right_hip_roll_link" pos="0 -0.052 -0.030465" quat="0.996179 0 -0.0873386 0">
          <inertial pos="0.029812 0.001045 -0.087934" quat="0.977808 1.97119e-05 0.205576 0.0403793" mass="1.52" diaginertia="0.00254986 0.00241169 0.00148755"/>
          <joint name="right_hip_roll_joint" pos="0 0 0" axis="1 0 0" range="-2.9671 0.5236" actuatorfrcrange="-139 139"/>
          <geom type="mesh" contype="0" conaffinity="0" group="1" density="0" rgba="0.7 0.7 0.7 1" mesh="right_hip_roll_link"/>
          <geom type="mesh" rgba="0.7 0.7 0.7 1" mesh="right_hip_roll_link"/>
          <body name="right_hip_yaw_link" pos="0.025001 0 -0.12412">
            <inertial pos="-0.057709 0.010981 -0.15078" quat="0.751181 0.223482 0.15832 0.600598" mass="1.702" diaginertia="0.00776166 0.00717575 0.00160139"/>
            <joint name="right_hip_yaw_joint" pos="0 0 0" axis="0 0 1" range="-2.7576 2.7576" actuatorfrcrange="-88 88"/>
            <geom type="mesh" contype="0" conaffinity="0" group="1" density="0" rgba="0.7 0.7 0.7 1" mesh="right_hip_yaw_link"/>
            <geom type="mesh" rgba="0.7 0.7 0.7 1" mesh="right_hip_yaw_link"/>
            <body name="right_knee_link" pos="-0.078273 -0.0021489 -0.17734" quat="0.996179 0 0.0873386 0">
              <inertial pos="0.005457 -0.003964 -0.12074" quat="0.923439 0.0345276 0.0116333 -0.382012" mass="1.932" diaginertia="0.011374 0.0112843 0.00146452"/>
              <joint name="right_knee_joint" pos="0 0 0" axis="0 1 0" range="-0.087267 2.8798" actuatorfrcrange="-139 139"/>
              <geom type="mesh" contype="0" conaffinity="0" group="1" density="0" rgba="0.7 0.7 0.7 1" mesh="right_knee_link"/>
              <geom type="mesh" rgba="0.7 0.7 0.7 1" mesh="right_knee_link"/>
              <body name="right_ankle_pitch_link" pos="0 9.4445e-05 -0.30001">
                <inertial pos="-0.007269 0 0.011137" quat="0.603053 0.369225 0.369225 0.603053" mass="0.074" diaginertia="1.89e-05 1.40805e-05 6.9195e-06"/>
                <joint name="right_ankle_pitch_joint" pos="0 0 0" axis="0 1 0" range="-0.87267 0.5236" actuatorfrcrange="-50 50"/>
                <geom type="mesh" contype="0" conaffinity="0" group="1" density="0" rgba="0.7 0.7 0.7 1" mesh="right_ankle_pitch_link"/>
                <geom type="mesh" rgba="0.7 0.7 0.7 1" mesh="right_ankle_pitch_link"/>
                <body name="right_ankle_roll_link" pos="0 0 -0.017558">
                  <inertial pos="0.026505 0 -0.016425" quat="0.000481092 0.728482 0.000618967 0.685065" mass="0.608" diaginertia="0.00167218 0.0016161 0.000217621"/>
                  <joint name="right_ankle_roll_joint" pos="0 0 0" axis="1 0 0" range="-0.2618 0.2618" actuatorfrcrange="-50 50"/>
                  <geom type="mesh" contype="0" conaffinity="0" group="1" density="0" rgba="0.2 0.2 0.2 1" mesh="right_ankle_roll_link"/>
                  <geom size="0.005" pos="-0.05 0.025 -0.03" rgba="0.2 0.2 0.2 1"/>
                  <geom size="0.005" pos="-0.05 -0.025 -0.03" rgba="0.2 0.2 0.2 1"/>
                  <geom size="0.005" pos="0.12 0.03 -0.03" rgba="0.2 0.2 0.2 1"/>
                  <geom size="0.005" pos="0.12 -0.03 -0.03" rgba="0.2 0.2 0.2 1"/>
                  <!-- Right foot contact site -->
                  <site name="right_foot_site" pos="0.03 0 -0.03" size="0.01"/>
                </body>
              </body>
            </body>
          </body>
        </body>
      </body>
    </body>
  </worldbody>

  <!-- Sensors -->
  <sensor>
    <!-- IMU in pelvis -->
    <gyro name="imu_gyro" site="imu_site" noise="0.0005"/>
    <accelerometer name="imu_accel" site="imu_site" noise="0.01"/>

    <!-- Foot contact forces (for touch sensing) -->
    <touch name="left_foot_touch" site="left_foot_site"/>
    <touch name="right_foot_touch" site="right_foot_site"/>

    <!-- LiDAR rangefinders (36 rays at 10° intervals) -->
    <!-- Range: 0.1m to 10m, cutoff returns -1 -->
    <rangefinder name="lidar-00" site="lidar-00" cutoff="10"/>
    <rangefinder name="lidar-01" site="lidar-01" cutoff="10"/>
    <rangefinder name="lidar-02" site="lidar-02" cutoff="10"/>
    <rangefinder name="lidar-03" site="lidar-03" cutoff="10"/>
    <rangefinder name="lidar-04" site="lidar-04" cutoff="10"/>
    <rangefinder name="lidar-05" site="lidar-05" cutoff="10"/>
    <rangefinder name="lidar-06" site="lidar-06" cutoff="10"/>
    <rangefinder name="lidar-07" site="lidar-07" cutoff="10"/>
    <rangefinder name="lidar-08" site="lidar-08" cutoff="10"/>
    <rangefinder name="lidar-09" site="lidar-09" cutoff="10"/>
    <rangefinder name="lidar-10" site="lidar-10" cutoff="10"/>
    <rangefinder name="lidar-11" site="lidar-11" cutoff="10"/>
    <rangefinder name="lidar-12" site="lidar-12" cutoff="10"/>
    <rangefinder name="lidar-13" site="lidar-13" cutoff="10"/>
    <rangefinder name="lidar-14" site="lidar-14" cutoff="10"/>
    <rangefinder name="lidar-15" site="lidar-15" cutoff="10"/>
    <rangefinder name="lidar-16" site="lidar-16" cutoff="10"/>
    <rangefinder name="lidar-17" site="lidar-17" cutoff="10"/>
    <rangefinder name="lidar-18" site="lidar-18" cutoff="10"/>
    <rangefinder name="lidar-19" site="lidar-19" cutoff="10"/>
    <rangefinder name="lidar-20" site="lidar-20" cutoff="10"/>
    <rangefinder name="lidar-21" site="lidar-21" cutoff="10"/>
    <rangefinder name="lidar-22" site="lidar-22" cutoff="10"/>
    <rangefinder name="lidar-23" site="lidar-23" cutoff="10"/>
    <rangefinder name="lidar-24" site="lidar-24" cutoff="10"/>
    <rangefinder name="lidar-25" site="lidar-25" cutoff="10"/>
    <rangefinder name="lidar-26" site="lidar-26" cutoff="10"/>
    <rangefinder name="lidar-27" site="lidar-27" cutoff="10"/>
    <rangefinder name="lidar-28" site="lidar-28" cutoff="10"/>
    <rangefinder name="lidar-29" site="lidar-29" cutoff="10"/>
    <rangefinder name="lidar-30" site="lidar-30" cutoff="10"/>
    <rangefinder name="lidar-31" site="lidar-31" cutoff="10"/>
    <rangefinder name="lidar-32" site="lidar-32" cutoff="10"/>
    <rangefinder name="lidar-33" site="lidar-33" cutoff="10"/>
    <rangefinder name="lidar-34" site="lidar-34" cutoff="10"/>
    <rangefinder name="lidar-35" site="lidar-35" cutoff="10"/>
  </sensor>

  <actuator>
    <motor name="left_hip_pitch_joint" joint="left_hip_pitch_joint"/>
    <motor name="left_hip_roll_joint" joint="left_hip_roll_joint"/>
    <motor name="left_hip_yaw_joint" joint="left_hip_yaw_joint"/>
    <motor name="left_knee_joint" joint="left_knee_joint"/>
    <motor name="left_ankle_pitch_joint" joint="left_ankle_pitch_joint"/>
    <motor name="left_ankle_roll_joint" joint="left_ankle_roll_joint"/>
    <motor name="right_hip_pitch_joint" joint="right_hip_pitch_joint"/>
    <motor name="right_hip_roll_joint" joint="right_hip_roll_joint"/>
    <motor name="right_hip_yaw_joint" joint="right_hip_yaw_joint"/>
    <motor name="right_knee_joint" joint="right_knee_joint"/>
    <motor name="right_ankle_pitch_joint" joint="right_ankle_pitch_joint"/>
    <motor name="right_ankle_roll_joint" joint="right_ankle_roll_joint"/>
  </actuator>
</mujoco>
